Workbook

Sheet Объединенные данные
A1: Year | B1: Month | C1: Channel | D1: Brand | E1: Weight range | F1: Units (in 1000) | G1: Value (in 1000 rub) | H1: Volume (in 1000 kg) | I1: Number of stores | J1: Units_outlier | K1: Value_outlier | L1: Volume_outlier | M1: Numb_stores_outlier | Q1: Расчет выбросов для числовых столбцов
A2: 2020 | B2: 11 | C2: Supermarkets | D2: Beige | E2: 200-249G | F2: 0.143 | G2: 65.889532 | H2: 0.0286 | I2: 0 | J2: =IF(OR(Копия_20206[[#This Row],[Units (in 1000)]]>$R$7,Копия_20206[[#This Row],[Units (in 1000)]]<$R$6),"outlier","not outlier") -> not outlier | K2: =IF(OR(Копия_20206[[#This Row],[Value (in 1000 rub)]]>$S$7,Копия_20206[[#This Row],[Value (in 1000 rub)]]<$S$6),"outlier","not outlier") -> not outlier | L2: =IF(OR(Копия_20206[[#This Row],[Volume (in 1000 kg)]]>$T$7,Копия_20206[[#This Row],[Volume (in 1000 kg)]]<$T$6),"outlier","not outlier") -> not outlier | M2: =IF(OR(Копия_20206[[#This Row],[Number of stores]]>$U$7,Копия_20206[[#This Row],[Number of stores]]<$U$6),"outlier","not outlier") -> not outlier | R2: Units_out | S2: Value_out | T2: Volume_out | U2: Numb_stores_out
A3: 2020 | B3: 11 | C3: Supermarkets | D3: Beige | E3: 350-399G | F3: 0.3131 | G3: 155.94172 | H3: 0.1096 | I3: 0 | J3: =IF(OR(Копия_20206[[#This Row],[Units (in 1000)]]>$R$7,Копия_20206[[#This Row],[Units (in 1000)]]<$R$6),"outlier","not outlier") -> not outlier | K3: =IF(OR(Копия_20206[[#This Row],[Value (in 1000 rub)]]>$S$7,Копия_20206[[#This Row],[Value (in 1000 rub)]]<$S$6),"outlier","not outlier") -> not outlier | L3: =IF(OR(Копия_20206[[#This Row],[Volume (in 1000 kg)]]>$T$7,Копия_20206[[#This Row],[Volume (in 1000 kg)]]<$T$6),"outlier","not outlier") -> not outlier | M3: =IF(OR(Копия_20206[[#This Row],[Number of stores]]>$U$7,Копия_20206[[#This Row],[Number of stores]]<$U$6),"outlier","not outlier") -> not outlier | Q3: Q_1 | R3: =_xlfn.QUARTILE.INC(Копия_20206[Units (in 1000)],1) -> 0.29015 | S3: =_xlfn.QUARTILE.INC(Копия_20206[Value (in 1000 rub)],1) -> 46.865592 | T3: =_xlfn.QUARTILE.INC(Копия_20206[Volume (in 1000 kg)],1) -> 0.099825 | U3: =_xlfn.QUARTILE.INC(Копия_20206[Number of stores],1) -> 22.75
A4: 2020 | B4: 12 | C4: Supermarkets | D4: Beige | E4: 200-249G | F4: 0.0765 | G4: 35.958112 | H4: 0.0153 | I4: 0 | J4: =IF(OR(Копия_20206[[#This Row],[Units (in 1000)]]>$R$7,Копия_20206[[#This Row],[Units (in 1000)]]<$R$6),"outlier","not outlier") -> not outlier | K4: =IF(OR(Копия_20206[[#This Row],[Value (in 1000 rub)]]>$S$7,Копия_20206[[#This Row],[Value (in 1000 rub)]]<$S$6),"outlier","not outlier") -> not outlier | L4: =IF(OR(Копия_20206[[#This Row],[Volume (in 1000 kg)]]>$T$7,Копия_20206[[#This Row],[Volume (in 1000 kg)]]<$T$6),"outlier","not outlier") -> not outlier | M4: =IF(OR(Копия_20206[[#This Row],[Number of stores]]>$U$7,Копия_20206[[#This Row],[Number of stores]]<$U$6),"outlier","not outlier") -> not outlier | Q4: Q_3 | R4: =_xlfn.QUARTILE.INC(Копия_20206[Units (in 1000)],3) -> 9.392675 | S4: =_xlfn.QUARTILE.INC(Копия_20206[Value (in 1000 rub)],3) -> 868.14471 | T4: =_xlfn.QUARTILE.INC(Копия_20206[Volume (in 1000 kg)],3) -> 3.003675 | U4: =_xlfn.QUARTILE.INC(Копия_20206[Number of stores],3) -> 1089.25
A5: 2020 | B5: 12 | C5: Supermarkets | D5: Beige | E5: 350-399G | F5: 0.2849 | G5: 140.16042 | H5: 0.0997 | I5: 0 | J5: =IF(OR(Копия_20206[[#This Row],[Units (in 1000)]]>$R$7,Копия_20206[[#This Row],[Units (in 1000)]]<$R$6),"outlier","not outlier") -> not outlier | K5: =IF(OR(Копия_20206[[#This Row],[Value (in 1000 rub)]]>$S$7,Копия_20206[[#This Row],[Value (in 1000 rub)]]<$S$6),"outlier","not outlier") -> not outlier | L5: =IF(OR(Копия_20206[[#This Row],[Volume (in 1000 kg)]]>$T$7,Копия_20206[[#This Row],[Volume (in 1000 kg)]]<$T$6),"outlier","not outlier") -> not outlier | M5: =IF(OR(Копия_20206[[#This Row],[Number of stores]]>$U$7,Копия_20206[[#This Row],[Number of stores]]<$U$6),"outlier","not outlier") -> not outlier | Q5: IQR | R5: =R4-R3 -> 9.102525 | S5: =S4-S3 -> 821.27912 | T5: =T4-T3 -> 2.90385 | U5: =U4-U3 -> 1066.5
A6: 2020 | B6: 1 | C6: Hypermarkets | D6: Black | E6: 200-249G | F6: 10.0639 | G6: 573.12876 | H6: 2.3147 | I6: 547 | J6: =IF(OR(Копия_20206[[#This Row],[Units (in 1000)]]>$R$7,Копия_20206[[#This Row],[Units (in 1000)]]<$R$6),"outlier","not outlier") -> not outlier | K6: =IF(OR(Копия_20206[[#This Row],[Value (in 1000 rub)]]>$S$7,Копия_20206[[#This Row],[Value (in 1000 rub)]]<$S$6),"outlier","not outlier") -> not outlier | L6: =IF(OR(Копия_20206[[#This Row],[Volume (in 1000 kg)]]>$T$7,Копия_20206[[#This Row],[Volume (in 1000 kg)]]<$T$6),"outlier","not outlier") -> not outlier | M6: =IF(OR(Копия_20206[[#This Row],[Number of stores]]>$U$7,Копия_20206[[#This Row],[Number of stores]]<$U$6),"outlier","not outlier") -> not outlier | Q6: lower_limit | R6: =R3-1.5*R5 -> -13.363637 | S6: =S3-1.5*S5 -> -1185.0531 | T6: =T3-1.5*T5 -> -4.25595 | U6: =U3-1.5*U5 -> -1577
A7: 2020 | B7: 1 | C7: Hypermarkets | D7: Black | E7: 400-599G | F7: 5.1222 | G7: 559.44438 | H7: 2.305 | I7: 325 | J7: =IF(OR(Копия_20206[[#This Row],[Units (in 1000)]]>$R$7,Копия_20206[[#This Row],[Units (in 1000)]]<$R$6),"outlier","not outlier") -> not outlier | K7: =IF(OR(Копия_20206[[#This Row],[Value (in 1000 rub)]]>$S$7,Копия_20206[[#This Row],[Value (in 1000 rub)]]<$S$6),"outlier","not outlier") -> not outlier | L7: =IF(OR(Копия_20206[[#This Row],[Volume (in 1000 kg)]]>$T$7,Копия_20206[[#This Row],[Volume (in 1000 kg)]]<$T$6),"outlier","not outlier") -> not outlier | M7: =IF(OR(Копия_20206[[#This Row],[Number of stores]]>$U$7,Копия_20206[[#This Row],[Number of stores]]<$U$6),"outlier","not outlier") -> not outlier | Q7: upper_limit | R7: =R4+1.5*R5 -> 23.046462 | S7: =S4+1.5*S5 -> 2100.0634 | T7: =T4+1.5*T5 -> 7.35945 | U7: =U4+1.5*U5 -> 2689
A8: 2020 | B8: 1 | C8: Minimarkets | D8: Black | E8: 200-249G | F8: 4.3366 | G8: 319.95177 | H8: 0.9974 | I8: 1627 | J8: =IF(OR(Копия_20206[[#This Row],[Units (in 1000)]]>$R$7,Копия_20206[[#This Row],[Units (in 1000)]]<$R$6),"outlier","not outlier") -> not outlier | K8: =IF(OR(Копия_20206[[#This Row],[Value (in 1000 rub)]]>$S$7,Копия_20206[[#This Row],[Value (in 1000 rub)]]<$S$6),"outlier","not outlier") -> not outlier | L8: =IF(OR(Копия_20206[[#This Row],[Volume (in 1000 kg)]]>$T$7,Копия_20206[[#This Row],[Volume (in 1000 kg)]]<$T$6),"outlier","not outlier") -> not outlier | M8: =IF(OR(Копия_20206[[#This Row],[Number of stores]]>$U$7,Копия_20206[[#This Row],[Number of stores]]<$U$6),"outlier","not outlier") -> not outlier
A9: 2020 | B9: 1 | C9: Minimarkets | D9: Black | E9: 400-599G | F9: 1.6089 | G9: 234.20046 | H9: 0.7239 | I9: 514 | J9: =IF(OR(Копия_20206[[#This Row],[Units (in 1000)]]>$R$7,Копия_20206[[#This Row],[Units (in 1000)]]<$R$6),"outlier","not outlier") -> not outlier | K9: =IF(OR(Копия_20206[[#This Row],[Value (in 1000 rub)]]>$S$7,Копия_20206[[#This Row],[Value (in 1000 rub)]]<$S$6),"outlier","not outlier") -> not outlier | L9: =IF(OR(Копия_20206[[#This Row],[Volume (in 1000 kg)]]>$T$7,Копия_20206[[#This Row],[Volume (in 1000 kg)]]<$T$6),"outlier","not outlier") -> not outlier | M9: =IF(OR(Копия_20206[[#This Row],[Number of stores]]>$U$7,Копия_20206[[#This Row],[Number of stores]]<$U$6),"outlier","not outlier") -> not outlier
A10: 2020 | B10: 1 | C10: Supermarkets | D10: Black | E10: 200-249G | F10: 19.5669 | G10: 1090.3411 | H10: 4.5003 | I10: 3312 | J10: =IF(OR(Копия_20206[[#This Row],[Units (in 1000)]]>$R$7,Копия_20206[[#This Row],[Units (in 1000)]]<$R$6),"outlier","not outlier") -> not outlier | K10: =IF(OR(Копия_20206[[#This Row],[Value (in 1000 rub)]]>$S$7,Копия_20206[[#This Row],[Value (in 1000 rub)]]<$S$6),"outlier","not outlier") -> not outlier | L10: =IF(OR(Копия_20206[[#This Row],[Volume (in 1000 kg)]]>$T$7,Копия_20206[[#This Row],[Volume (in 1000 kg)]]<$T$6),"outlier","not outlier") -> not outlier | M10: =IF(OR(Копия_20206[[#This Row],[Number of stores]]>$U$7,Копия_20206[[#This Row],[Number of stores]]<$U$6),"outlier","not outlier") -> outlier
A11: 2020 | B11: 1 | C11: Supermarkets | D11: Black | E11: 400-599G | F11: 7.0743 | G11: 918.30979 | H11: 3.1834 | I11: 1018 | J11: =IF(OR(Копия_20206[[#This Row],[Units (in 1000)]]>$R$7,Копия_20206[[#This Row],[Units (in 1000)]]<$R$6),"outlier","not outlier") -> not outlier | K11: =IF(OR(Копия_20206[[#This Row],[Value (in 1000 rub)]]>$S$7,Копия_20206[[#This Row],[Value (in 1000 rub)]]<$S$6),"outlier","not outlier") -> not outlier | L11: =IF(OR(Копия_20206[[#This Row],[Volume (in 1000 kg)]]>$T$7,Копия_20206[[#This Row],[Volume (in 1000 kg)]]<$T$6),"outlier","not outlier") -> not outlier | M11: =IF(OR(Копия_20206[[#This Row],[Number of stores]]>$U$7,Копия_20206[[#This Row],[Number of stores]]<$U$6),"outlier","not outlier") -> not outlier
A12: 2020 | B12: 2 | C12: Hypermarkets | D12: Black | E12: 200-249G | F12: 16.1499 | G12: 874.32413 | H12: 3.7145 | I12: 525 | J12: =IF(OR(Копия_20206[[#This Row],[Units (in 1000)]]>$R$7,Копия_20206[[#This Row],[Units (in 1000)]]<$R$6),"outlier","not outlier") -> not outlier | K12: =IF(OR(Копия_20206[[#This Row],[Value (in 1000 rub)]]>$S$7,Копия_20206[[#This Row],[Value (in 1000 rub)]]<$S$6),"outlier","not outlier") -> not outlier | L12: =IF(OR(Копия_20206[[#This Row],[Volume (in 1000 kg)]]>$T$7,Копия_20206[[#This Row],[Volume (in 1000 kg)]]<$T$6),"outlier","not outlier") -> not outlier | M12: =IF(OR(Копия_20206[[#This Row],[Number of stores]]>$U$7,Копия_20206[[#This Row],[Number of stores]]<$U$6),"outlier","not outlier") -> not outlier
A13: 2020 | B13: 2 | C13: Hypermarkets | D13: Black | E13: 400-599G | F13: 3.4374 | G13: 443.55682 | H13: 1.5468 | I13: 319 | J13: =IF(OR(Копия_20206[[#This Row],[Units (in 1000)]]>$R$7,Копия_20206[[#This Row],[Units (in 1000)]]<$R$6),"outlier","not outlier") -> not outlier | K13: =IF(OR(Копия_20206[[#This Row],[Value (in 1000 rub)]]>$S$7,Копия_20206[[#This Row],[Value (in 1000 rub)]]<$S$6),"outlier","not outlier") -> not outlier | L13: =IF(OR(Копия_20206[[#This Row],[Volume (in 1000 kg)]]>$T$7,Копия_20206[[#This Row],[Volume (in 1000 kg)]]<$T$6),"outlier","not outlier") -> not outlier | M13: =IF(OR(Копия_20206[[#This Row],[Number of stores]]>$U$7,Копия_20206[[#This Row],[Number of stores]]<$U$6),"outlier","not outlier") -> not outlier
A14: 2020 | B14: 2 | C14: Minimarkets | D14: Black | E14: 200-249G | F14: 2.6972 | G14: 195.33986 | H14: 0.6204 | I14: 1549 | J14: =IF(OR(Копия_20206[[#This Row],[Units (in 1000)]]>$R$7,Копия_20206[[#This Row],[Units (in 1000)]]<$R$6),"outlier","not outlier") -> not outlier | K14: =IF(OR(Копия_20206[[#This Row],[Value (in 1000 rub)]]>$S$7,Копия_20206[[#This Row],[Value (in 1000 rub)]]<$S$6),"outlier","not outlier") -> not outlier | L14: =IF(OR(Копия_20206[[#This Row],[Volume (in 1000 kg)]]>$T$7,Копия_20206[[#This Row],[Volume (in 1000 kg)]]<$T$6),"outlier","not outlier") -> not outlier | M14: =IF(OR(Копия_20206[[#This Row],[Number of stores]]>$U$7,Копия_20206[[#This Row],[Number of stores]]<$U$6),"outlier","not outlier") -> not outlier
A15: 2020 | B15: 2 | C15: Minimarkets | D15: Black | E15: 400-599G | F15: 1.1557 | G15: 203.56772 | H15: 0.5201 | I15: 518 | J15: =IF(OR(Копия_20206[[#This Row],[Units (in 1000)]]>$R$7,Копия_20206[[#This Row],[Units (in 1000)]]<$R$6),"outlier","not outlier") -> not outlier | K15: =IF(OR(Копия_20206[[#This Row],[Value (in 1000 rub)]]>$S$7,Копия_20206[[#This Row],[Value (in 1000 rub)]]<$S$6),"outlier","not outlier") -> not outlier | L15: =IF(OR(Копия_20206[[#This Row],[Volume (in 1000 kg)]]>$T$7,Копия_20206[[#This Row],[Volume (in 1000 kg)]]<$T$6),"outlier","not outlier") -> not outlier | M15: =IF(OR(Копия_20206[[#This Row],[Number of stores]]>$U$7,Копия_20206[[#This Row],[Number of stores]]<$U$6),"outlier","not outlier") -> not outlier
A16: 2020 | B16: 2 | C16: Supermarkets | D16: Black | E16: 200-249G | F16: 9.44 | G16: 564.16192 | H16: 2.1712 | I16: 2546 | J16: =IF(OR(Копия_20206[[#This Row],[Units (in 1000)]]>$R$7,Копия_20206[[#This Row],[Units (in 1000)]]<$R$6),"outlier","not outlier") -> not outlier | K16: =IF(OR(Копия_20206[[#This Row],[Value (in 1000 rub)]]>$S$7,Копия_20206[[#This Row],[Value (in 1000 rub)]]<$S$6),"outlier","not outlier") -> not outlier | L16: =IF(OR(Копия_20206[[#This Row],[Volume (in 1000 kg)]]>$T$7,Копия_20206[[#This Row],[Volume (in 1000 kg)]]<$T$6),"outlier","not outlier") -> not outlier | M16: =IF(OR(Копия_20206[[#This Row],[Number of stores]]>$U$7,Копия_20206[[#This Row],[Number of stores]]<$U$6),"outlier","not outlier") -> not outlier
A17: 2020 | B17: 2 | C17: Supermarkets | D17: Black | E17: 400-599G | F17: 5.2153 | G17: 824.08277 | H17: 2.3468 | I17: 1093 | J17: =IF(OR(Копия_20206[[#This Row],[Units (in 1000)]]>$R$7,Копия_20206[[#This Row],[Units (in 1000)]]<$R$6),"outlier","not outlier") -> not outlier | K17: =IF(OR(Копия_20206[[#This Row],[Value (in 1000 rub)]]>$S$7,Копия_20206[[#This Row],[Value (in 1000 rub)]]<$S$6),"outlier","not outlier") -> not outlier | L17: =IF(OR(Копия_20206[[#This Row],[Volume (in 1000 kg)]]>$T$7,Копия_20206[[#This Row],[Volume (in 1000 kg)]]<$T$6),"outlier","not outlier") -> not outlier | M17: =IF(OR(Копия_20206[[#This Row],[Number of stores]]>$U$7,Копия_20206[[#This Row],[Number of stores]]<$U$6),"outlier","not outlier") -> not outlier
A18: 2020 | B18: 3 | C18: Hypermarkets | D18: Black | E18: 200-249G | F18: 11.6185 | G18: 677.01797 | H18: 2.6723 | I18: 503 | J18: =IF(OR(Копия_20206[[#This Row],[Units (in 1000)]]>$R$7,Копия_20206[[#This Row],[Units (in 1000)]]<$R$6),"outlier","not outlier") -> not outlier | K18: =IF(OR(Копия_20206[[#This Row],[Value (in 1000 rub)]]>$S$7,Копия_20206[[#This Row],[Value (in 1000 rub)]]<$S$6),"outlier","not outlier") -> not outlier | L18: =IF(OR(Копия_20206[[#This Row],[Volume (in 1000 kg)]]>$T$7,Копия_20206[[#This Row],[Volume (in 1000 kg)]]<$T$6),"outlier","not outlier") -> not outlier | M18: =IF(OR(Копия_20206[[#This Row],[Number of stores]]>$U$7,Копия_20206[[#This Row],[Number of stores]]<$U$6),"outlier","not outlier") -> not outlier
A19: 2020 | B19: 3 | C19: Hypermarkets | D19: Black | E19: 300-349G | F19: 0.0006 | G19: 0.042303 | H19: 0.0002 | I19: 2 | J19: =IF(OR(Копия_20206[[#This Row],[Units (in 1000)]]>$R$7,Копия_20206[[#This Row],[Units (in 1000)]]<$R$6),"outlier","not outlier") -> not outlier | K19: =IF(OR(Копия_20206[[#This Row],[Value (in 1000 rub)]]>$S$7,Копия_20206[[#This Row],[Value (in 1000 rub)]]<$S$6),"outlier","not outlier") -> not outlier | L19: =IF(OR(Копия_20206[[#This Row],[Volume (in 1000 kg)]]>$T$7,Копия_20206[[#This Row],[Volume (in 1000 kg)]]<$T$6),"outlier","not outlier") -> not outlier | M19: =IF(OR(Копия_20206[[#This Row],[Number of stores]]>$U$7,Копия_20206[[#This Row],[Number of stores]]<$U$6),"outlier","not outlier") -> not outlier
... A26: 2020 | B26: 4 | C26: Hypermarkets | D26: Black | E26: 200-249G | F26: 10.8278 | G26: 634.09898 | H26: 2.4904 | I26: 482 | J26: =IF(OR(Копия_20206[[#This Row],[Units (in 1000)]]>$R$7,Копия_20206[[#This Row],[Units (in 1000)]]<$R$6),"outlier","not outlier") -> not outlier | K26: =IF(OR(Копия_20206[[#This Row],[Value (in 1000 rub)]]>$S$7,Копия_20206[[#This Row],[Value (in 1000 rub)]]<$S$6),"outlier","not outlier") -> not outlier | L26: =IF(OR(Копия_20206[[#This Row],[Volume (in 1000 kg)]]>$T$7,Копия_20206[[#This Row],[Volume (in 1000 kg)]]<$T$6),"outlier","not outlier") -> not outlier | M26: =IF(OR(Копия_20206[[#This Row],[Number of stores]]>$U$7,Копия_20206[[#This Row],[Number of stores]]<$U$6),"outlier","not outlier") -> not outlier
A27: 2020 | B27: 4 | C27: Hypermarkets | D27: Black | E27: 300-349G | F27: 0.0001 | G27: 0.007028 | H27: 0 | I27: 0 | J27: =IF(OR(Копия_20206[[#This Row],[Units (in 1000)]]>$R$7,Копия_20206[[#This Row],[Units (in 1000)]]<$R$6),"outlier","not outlier") -> not outlier | K27: =IF(OR(Копия_20206[[#This Row],[Value (in 1000 rub)]]>$S$7,Копия_20206[[#This Row],[Value (in 1000 rub)]]<$S$6),"outlier","not outlier") -> not outlier | L27: =IF(OR(Копия_20206[[#This Row],[Volume (in 1000 kg)]]>$T$7,Копия_20206[[#This Row],[Volume (in 1000 kg)]]<$T$6),"outlier","not outlier") -> outlier | M27: =IF(OR(Копия_20206[[#This Row],[Number of stores]]>$U$7,Копия_20206[[#This Row],[Number of stores]]<$U$6),"outlier","not outlier") -> not outlier
A28: 2020 | B28: 4 | C28: Hypermarkets | D28: Black | E28: 400-599G | F28: 2.0152 | G28: 337.34259 | H28: 0.9069 | I28: 302 | J28: =IF(OR(Копия_20206[[#This Row],[Units (in 1000)]]>$R$7,Копия_20206[[#This Row],[Units (in 1000)]]<$R$6),"outlier","not outlier") -> not outlier | K28: =IF(OR(Копия_20206[[#This Row],[Value (in 1000 rub)]]>$S$7,Копия_20206[[#This Row],[Value (in 1000 rub)]]<$S$6),"outlier","not outlier") -> not outlier | L28: =IF(OR(Копия_20206[[#This Row],[Volume (in 1000 kg)]]>$T$7,Копия_20206[[#This Row],[Volume (in 1000 kg)]]<$T$6),"outlier","not outlier") -> not outlier | M28: =IF(OR(Копия_20206[[#This Row],[Number of stores]]>$U$7,Копия_20206[[#This Row],[Number of stores]]<$U$6),"outlier","not outlier") -> not outlier
A29: 2020 | B29: 4 | C29: Hypermarkets | D29: Black | E29: 600-899G | F29: 0.0001 | G29: 0.016112 | H29: 0.0001 | I29: 2 | J29: =IF(OR(Копия_20206[[#This Row],[Units (in 1000)]]>$R$7,Копия_20206[[#This Row],[Units (in 1000)]]<$R$6),"outlier","not outlier") -> not outlier | K29: =IF(OR(Копия_20206[[#This Row],[Value (in 1000 rub)]]>$S$7,Копия_20206[[#This Row],[Value (in 1000 rub)]]<$S$6),"outlier","not outlier") -> not outlier | L29: =IF(OR(Копия_20206[[#This Row],[Volume (in 1000 kg)]]>$T$7,Копия_20206[[#This Row],[Volume (in 1000 kg)]]<$T$6),"outlier","not outlier") -> not outlier | M29: =IF(OR(Копия_20206[[#This Row],[Number of stores]]>$U$7,Копия_20206[[#This Row],[Number of stores]]<$U$6),"outlier","not outlier") -> not outlier
A30: 2020 | B30: 4 | C30: Minimarkets | D30: Black | E30: 200-249G | F30: 3.1584 | G30: 225.61309 | H30: 0.7264 | I30: 1774 | J30: =IF(OR(Копия_20206[[#This Row],[Units (in 1000)]]>$R$7,Копия_20206[[#This Row],[Units (in 1000)]]<$R$6),"outlier","not outlier") -> not outlier | K30: =IF(OR(Копия_20206[[#This Row],[Value (in 1000 rub)]]>$S$7,Копия_20206[[#This Row],[Value (in 1000 rub)]]<$S$6),"outlier","not outlier") -> not outlier | L30: =IF(OR(Копия_20206[[#This Row],[Volume (in 1000 kg)]]>$T$7,Копия_20206[[#This Row],[Volume (in 1000 kg)]]<$T$6),"outlier","not outlier") -> not outlier | M30: =IF(OR(Копия_20206[[#This Row],[Number of stores]]>$U$7,Копия_20206[[#This Row],[Number of stores]]<$U$6),"outlier","not outlier") -> not outlier
A31: 2020 | B31: 4 | C31: Minimarkets | D31: Black | E31: 400-599G | F31: 1.2491 | G31: 242.38945 | H31: 0.5621 | I31: 580 | J31: =IF(OR(Копия_20206[[#This Row],[Units (in 1000)]]>$R$7,Копия_20206[[#This Row],[Units (in 1000)]]<$R$6),"outlier","not outlier") -> not outlier | K31: =IF(OR(Копия_20206[[#This Row],[Value (in 1000 rub)]]>$S$7,Копия_20206[[#This Row],[Value (in 1000 rub)]]<$S$6),"outlier","not outlier") -> not outlier | L31: =IF(OR(Копия_20206[[#This Row],[Volume (in 1000 kg)]]>$T$7,Копия_20206[[#This Row],[Volume (in 1000 kg)]]<$T$6),"outlier","not outlier") -> not outlier | M31: =IF(OR(Копия_20206[[#This Row],[Number of stores]]>$U$7,Копия_20206[[#This Row],[Number of stores]]<$U$6),"outlier","not outlier") -> not outlier
A32: 2020 | B32: 4 | C32: Supermarkets | D32: Black | E32: 200-249G | F32: 4.8246 | G32: 343.43048 | H32: 1.1096 | I32: 1399 | J32: =IF(OR(Копия_20206[[#This Row],[Units (in 1000)]]>$R$7,Копия_20206[[#This Row],[Units (in 1000)]]<$R$6),"outlier","not outlier") -> not outlier | K32: =IF(OR(Копия_20206[[#This Row],[Value (in 1000 rub)]]>$S$7,Копия_20206[[#This Row],[Value (in 1000 rub)]]<$S$6),"outlier","not outlier") -> not outlier | L32: =IF(OR(Копия_20206[[#This Row],[Volume (in 1000 kg)]]>$T$7,Копия_20206[[#This Row],[Volume (in 1000 kg)]]<$T$6),"outlier","not outlier") -> not outlier | M32: =IF(OR(Копия_20206[[#This Row],[Number of stores]]>$U$7,Копия_20206[[#This Row],[Number of stores]]<$U$6),"outlier","not outlier") -> not outlier
A33: 2020 | B33: 4 | C33: Supermarkets | D33: Black | E33: 400-599G | F33: 3.4998 | G33: 654.63755 | H33: 1.5748 | I33: 1473 | J33: =IF(OR(Копия_20206[[#This Row],[Units (in 1000)]]>$R$7,Копия_20206[[#This Row],[Units (in 1000)]]<$R$6),"outlier","not outlier") -> not outlier | K33: =IF(OR(Копия_20206[[#This Row],[Value (in 1000 rub)]]>$S$7,Копия_20206[[#This Row],[Value (in 1000 rub)]]<$S$6),"outlier","not outlier") -> not outlier | L33: =IF(OR(Копия_20206[[#This Row],[Volume (in 1000 kg)]]>$T$7,Копия_20206[[#This Row],[Volume (in 1000 kg)]]<$T$6),"outlier","not outlier") -> not outlier | M33: =IF(OR(Копия_20206[[#This Row],[Number of stores]]>$U$7,Копия_20206[[#This Row],[Number of stores]]<$U$6),"outlier","not outlier") -> not outlier
A34: 2020 | B34: 5 | C34: Hypermarkets | D34: Black | E34: 200-249G | F34: 12.0351 | G34: 665.21681 | H34: 2.7681 | I34: 478 | J34: =IF(OR(Копия_20206[[#This Row],[Units (in 1000)]]>$R$7,Копия_20206[[#This Row],[Units (in 1000)]]<$R$6),"outlier","not outlier") -> not outlier | K34: =IF(OR(Копия_20206[[#This Row],[Value (in 1000 rub)]]>$S$7,Копия_20206[[#This Row],[Value (in 1000 rub)]]<$S$6),"outlier","not outlier") -> not outlier | L34: =IF(OR(Копия_20206[[#This Row],[Volume (in 1000 kg)]]>$T$7,Копия_20206[[#This Row],[Volume (in 1000 kg)]]<$T$6),"outlier","not outlier") -> not outlier | M34: =IF(OR(Копия_20206[[#This Row],[Number of stores]]>$U$7,Копия_20206[[#This Row],[Number of stores]]<$U$6),"outlier","not outlier") -> not outlier
A35: 2020 | B35: 5 | C35: Hypermarkets | D35: Black | E35: 400-599G | F35: 1.8037 | G35: 280.36658 | H35: 0.8117 | I35: 285 | J35: =IF(OR(Копия_20206[[#This Row],[Units (in 1000)]]>$R$7,Копия_20206[[#This Row],[Units (in 1000)]]<$R$6),"outlier","not outlier") -> not outlier | K35: =IF(OR(Копия_20206[[#This Row],[Value (in 1000 rub)]]>$S$7,Копия_20206[[#This Row],[Value (in 1000 rub)]]<$S$6),"outlier","not outlier") -> not outlier | L35: =IF(OR(Копия_20206[[#This Row],[Volume (in 1000 kg)]]>$T$7,Копия_20206[[#This Row],[Volume (in 1000 kg)]]<$T$6),"outlier","not outlier") -> not outlier | M35: =IF(OR(Копия_20206[[#This Row],[Number of stores]]>$U$7,Копия_20206[[#This Row],[Number of stores]]<$U$6),"outlier","not outlier") -> not outlier
A36: 2020 | B36: 5 | C36: Minimarkets | D36: Black | E36: 200-249G | F36: 3.7982 | G36: 283.98975 | H36: 0.8736 | I36: 1569 | J36: =IF(OR(Копия_20206[[#This Row],[Units (in 1000)]]>$R$7,Копия_20206[[#This Row],[Units (in 1000)]]<$R$6),"outlier","not outlier") -> not outlier | K36: =IF(OR(Копия_20206[[#This Row],[Value (in 1000 rub)]]>$S$7,Копия_20206[[#This Row],[Value (in 1000 rub)]]<$S$6),"outlier","not outlier") -> not outlier | L36: =IF(OR(Копия_20206[[#This Row],[Volume (in 1000 kg)]]>$T$7,Копия_20206[[#This Row],[Volume (in 1000 kg)]]<$T$6),"outlier","not outlier") -> not outlier | M36: =IF(OR(Копия_20206[[#This Row],[Number of stores]]>$U$7,Копия_20206[[#This Row],[Number of stores]]<$U$6),"outlier","not outlier") -> not outlier
A37: 2020 | B37: 5 | C37: Minimarkets | D37: Black | E37: 400-599G | F37: 0.6053 | G37: 112.81129 | H37: 0.2724 | I37: 330 | J37: =IF(OR(Копия_20206[[#This Row],[Units (in 1000)]]>$R$7,Копия_20206[[#This Row],[Units (in 1000)]]<$R$6),"outlier","not outlier") -> not outlier | K37: =IF(OR(Копия_20206[[#This Row],[Value (in 1000 rub)]]>$S$7,Копия_20206[[#This Row],[Value (in 1000 rub)]]<$S$6),"outlier","not outlier") -> not outlier | L37: =IF(OR(Копия_20206[[#This Row],[Volume (in 1000 kg)]]>$T$7,Копия_20206[[#This Row],[Volume (in 1000 kg)]]<$T$6),"outlier","not outlier") -> not outlier | M37: =IF(OR(Копия_20206[[#This Row],[Number of stores]]>$U$7,Копия_20206[[#This Row],[Number of stores]]<$U$6),"outlier","not outlier") -> not outlier
A38: 2020 | B38: 5 | C38: Supermarkets | D38: Black | E38: 200-249G | F38: 8.3302 | G38: 493.35294 | H38: 1.9159 | I38: 1621 | J38: =IF(OR(Копия_20206[[#This Row],[Units (in 1000)]]>$R$7,Копия_20206[[#This Row],[Units (in 1000)]]<$R$6),"outlier","not outlier") -> not outlier | K38: =IF(OR(Копия_20206[[#This Row],[Value (in 1000 rub)]]>$S$7,Копия_20206[[#This Row],[Value (in 1000 rub)]]<$S$6),"outlier","not outlier") -> not outlier | L38: =IF(OR(Копия_20206[[#This Row],[Volume (in 1000 kg)]]>$T$7,Копия_20206[[#This Row],[Volume (in 1000 kg)]]<$T$6),"outlier","not outlier") -> not outlier | M38: =IF(OR(Копия_20206[[#This Row],[Number of stores]]>$U$7,Копия_20206[[#This Row],[Number of stores]]<$U$6),"outlier","not outlier") -> not outlier
A39: 2020 | B39: 5 | C39: Supermarkets | D39: Black | E39: 400-599G | F39: 3.6336 | G39: 655.2646 | H39: 1.6351 | I39: 1225 | J39: =IF(OR(Копия_20206[[#This Row],[Units (in 1000)]]>$R$7,Копия_20206[[#This Row],[Units (in 1000)]]<$R$6),"outlier","not outlier") -> not outlier | K39: =IF(OR(Копия_20206[[#This Row],[Value (in 1000 rub)]]>$S$7,Копия_20206[[#This Row],[Value (in 1000 rub)]]<$S$6),"outlier","not outlier") -> not outlier | L39: =IF(OR(Копия_20206[[#This Row],[Volume (in 1000 kg)]]>$T$7,Копия_20206[[#This Row],[Volume (in 1000 kg)]]<$T$6),"outlier","not outlier") -> not outlier | M39: =IF(OR(Копия_20206[[#This Row],[Number of stores]]>$U$7,Копия_20206[[#This Row],[Number of stores]]<$U$6),"outlier","not outlier") -> not outlier
... A299: 2020 | B299: 7 | C299: Minimarkets | D299: Green | E299: 200-249G | F299: 50.7063 | G299: 3398.473 | H299: 10.6483 | I299: 8349 | J299: =IF(OR(Копия_20206[[#This Row],[Units (in 1000)]]>$R$7,Копия_20206[[#This Row],[Units (in 1000)]]<$R$6),"outlier","not outlier") -> outlier | K299: =IF(OR(Копия_20206[[#This Row],[Value (in 1000 rub)]]>$S$7,Копия_20206[[#This Row],[Value (in 1000 rub)]]<$S$6),"outlier","not outlier") -> outlier | L299: =IF(OR(Копия_20206[[#This Row],[Volume (in 1000 kg)]]>$T$7,Копия_20206[[#This Row],[Volume (in 1000 kg)]]<$T$6),"outlier","not outlier") -> outlier | M299: =IF(OR(Копия_20206[[#This Row],[Number of stores]]>$U$7,Копия_20206[[#This Row],[Number of stores]]<$U$6),"outlier","not outlier") -> outlier
A300: 2020 | B300: 7 | C300: Minimarkets | D300: Green | E300: 300-349G | F300: 0.0001 | G300: 0.010941 | H300: 0 | I300: 0 | J300: =IF(OR(Копия_20206[[#This Row],[Units (in 1000)]]>$R$7,Копия_20206[[#This Row],[Units (in 1000)]]<$R$6),"outlier","not outlier") -> not outlier | K300: =IF(OR(Копия_20206[[#This Row],[Value (in 1000 rub)]]>$S$7,Копия_20206[[#This Row],[Value (in 1000 rub)]]<$S$6),"outlier","not outlier") -> not outlier | L300: =IF(OR(Копия_20206[[#This Row],[Volume (in 1000 kg)]]>$T$7,Копия_20206[[#This Row],[Volume (in 1000 kg)]]<$T$6),"outlier","not outlier") -> outlier | M300: =IF(OR(Копия_20206[[#This Row],[Number of stores]]>$U$7,Копия_20206[[#This Row],[Number of stores]]<$U$6),"outlier","not outlier") -> not outlier
A301: 2020 | B301: 7 | C301: Minimarkets | D301: Green | E301: 350-399G | F301: 63.5335 | G301: 5999.0034 | H301: 22.2367 | I301: 8630 | J301: =IF(OR(Копия_20206[[#This Row],[Units (in 1000)]]>$R$7,Копия_20206[[#This Row],[Units (in 1000)]]<$R$6),"outlier","not outlier") -> outlier | K301: =IF(OR(Копия_20206[[#This Row],[Value (in 1000 rub)]]>$S$7,Копия_20206[[#This Row],[Value (in 1000 rub)]]<$S$6),"outlier","not outlier") -> outlier | L301: =IF(OR(Копия_20206[[#This Row],[Volume (in 1000 kg)]]>$T$7,Копия_20206[[#This Row],[Volume (in 1000 kg)]]<$T$6),"outlier","not outlier") -> outlier | M301: =IF(OR(Копия_20206[[#This Row],[Number of stores]]>$U$7,Копия_20206[[#This Row],[Number of stores]]<$U$6),"outlier","not outlier") -> outlier
A302: 2020 | B302: 7 | C302: Minimarkets | D302: Green | E302: 400-599G | F302: 6.463 | G302: 909.79536 | H302: 3.2316 | I302: 1457 | J302: =IF(OR(Копия_20206[[#This Row],[Units (in 1000)]]>$R$7,Копия_20206[[#This Row],[Units (in 1000)]]<$R$6),"outlier","not outlier") -> not outlier | K302: =IF(OR(Копия_20206[[#This Row],[Value (in 1000 rub)]]>$S$7,Копия_20206[[#This Row],[Value (in 1000 rub)]]<$S$6),"outlier","not outlier") -> not outlier | L302: =IF(OR(Копия_20206[[#This Row],[Volume (in 1000 kg)]]>$T$7,Копия_20206[[#This Row],[Volume (in 1000 kg)]]<$T$6),"outlier","not outlier") -> not outlier | M302: =IF(OR(Копия_20206[[#This Row],[Number of stores]]>$U$7,Копия_20206[[#This Row],[Number of stores]]<$U$6),"outlier","not outlier") -> not outlier
A303: 2020 | B303: 7 | C303: Minimarkets | D303: Green | E303: 600-899G | F303: 0.4626 | G303: 79.825211 | H303: 0.347 | I303: 307 | J303: =IF(OR(Копия_20206[[#This Row],[Units (in 1000)]]>$R$7,Копия_20206[[#This Row],[Units (in 1000)]]<$R$6),"outlier","not outlier") -> not outlier | K303: =IF(OR(Копия_20206[[#This Row],[Value (in 1000 rub)]]>$S$7,Копия_20206[[#This Row],[Value (in 1000 rub)]]<$S$6),"outlier","not outlier") -> not outlier | L303: =IF(OR(Копия_20206[[#This Row],[Volume (in 1000 kg)]]>$T$7,Копия_20206[[#This Row],[Volume (in 1000 kg)]]<$T$6),"outlier","not outlier") -> not outlier | M303: =IF(OR(Копия_20206[[#This Row],[Number of stores]]>$U$7,Копия_20206[[#This Row],[Number of stores]]<$U$6),"outlier","not outlier") -> not outlier
A304: 2020 | B304: 7 | C304: Supermarkets | D304: Green | E304: 200-249G | F304: 86.1022 | G304: 5422.055 | H304: 18.0815 | I304: 11371 | J304: =IF(OR(Копия_20206[[#This Row],[Units (in 1000)]]>$R$7,Копия_20206[[#This Row],[Units (in 1000)]]<$R$6),"outlier","not outlier") -> outlier | K304: =IF(OR(Копия_20206[[#This Row],[Value (in 1000 rub)]]>$S$7,Копия_20206[[#This Row],[Value (in 1000 rub)]]<$S$6),"outlier","not outlier") -> outlier | L304: =IF(OR(Копия_20206[[#This Row],[Volume (in 1000 kg)]]>$T$7,Копия_20206[[#This Row],[Volume (in 1000 kg)]]<$T$6),"outlier","not outlier") -> outlier | M304: =IF(OR(Копия_20206[[#This Row],[Number of stores]]>$U$7,Копия_20206[[#This Row],[Number of stores]]<$U$6),"outlier","not outlier") -> outlier
A305: 2020 | B305: 7 | C305: Supermarkets | D305: Green | E305: 350-399G | F305: 67.7327 | G305: 5977.6978 | H305: 23.7064 | I305: 7935 | J305: =IF(OR(Копия_20206[[#This Row],[Units (in 1000)]]>$R$7,Копия_20206[[#This Row],[Units (in 1000)]]<$R$6),"outlier","not outlier") -> outlier | K305: =IF(OR(Копия_20206[[#This Row],[Value (in 1000 rub)]]>$S$7,Копия_20206[[#This Row],[Value (in 1000 rub)]]<$S$6),"outlier","not outlier") -> outlier | L305: =IF(OR(Копия_20206[[#This Row],[Volume (in 1000 kg)]]>$T$7,Копия_20206[[#This Row],[Volume (in 1000 kg)]]<$T$6),"outlier","not outlier") -> outlier | M305: =IF(OR(Копия_20206[[#This Row],[Number of stores]]>$U$7,Копия_20206[[#This Row],[Number of stores]]<$U$6),"outlier","not outlier") -> outlier
...

Sheet Расчет метрик
A1: Динамика роста продаж в деньгах бренда Green за 2021 и 2022 года
B2: 2020 | C2: 2021 | D2: 2022
A3: FY | B3: =H17 -> 496393.4 | C3: =I17 -> 522684.06 | D3: =J17 -> 500728.41
A4: abs | B4: =H18 -> 0 | C4: =I18 -> 26290.664 | D4: =J18 -> -21955.647
A5: % | B5: =H19 -> 0 | C5: =I19 -> 0.052963363 | D5: =J19 -> -0.04200558
A6: L3M | B6: =H20 -> 132694.48 | C6: =I20 -> 135235.6 | D6: =J20 -> 114901.25
A7: abs | B7: =H21 -> 0 | C7: =I21 -> 2541.1255 | D7: =J21 -> -20334.352
A8: % | B8: =H22 -> 0 | C8: =I22 -> 0.019150198 | D8: =J22 -> -0.15036242
A9: M2M | B9: =H23 -> 45310.787 | C9: =I23 -> 43809.542 | D9: =J23 -> 35212.074
A10: abs | B10: =H24 -> 0 | C10: =I24 -> -1501.2449 | D10: =J24 -> -8597.4689
A11: % | B11: =H25 -> 0 | C11: =I25 -> -0.033132174 | D11: =J25 -> -0.19624649
A14: Динамика роста продаж в деньгах для всего рынка за 2021 и 2022 года
B15: бренд Blue | E15: бренд Deep | H15: бренд Green | K15: бренд Orange | N15: бренд Red | Q15: бренд White | T15: бренд Yellow
A16: год | B16: 2020 | C16: 2021 | D16: 2022 | E16: 2020 | F16: 2021 | G16: 2022 | H16: 2020 | I16: 2021 | J16: 2022 | K16: 2020 | L16: 2021 | M16: 2022 | N16: 2020 | O16: 2021 | P16: 2022 | Q16: 2020 | R16: 2021 | S16: 2022 | T16: 2020 | U16: 2021 | V16: 2022
A17: FY | B17: =SUM('Объединенные данные'!G84:G126) -> 137428.51 | C17: =SUM('Объединенные данные'!G714:G785) -> 163431.95 | D17: =SUM('Объединенные данные'!G1339:G1410) -> 221366.5 | E17: =SUM('Объединенные данные'!G133:G170) -> 5688.7063 | F17: =SUM('Объединенные данные'!G805:G840) -> 5259.9316 | G17: =SUM('Объединенные данные'!G1421:G1456) -> 5900.4471 | H17: =SUM('Объединенные данные'!G217:G378) -> 496393.4 | I17: =SUM('Объединенные данные'!G890:G1058) -> 522684.06 | J17: =SUM('Объединенные данные'!G1465:G1631) -> 500728.41 | K17: =SUM('Объединенные данные'!G402:G445) -> 1878.9583 | L17: =SUM('Объединенные данные'!G1102:G1143) -> 2601.1356 | M17: =SUM('Объединенные данные'!G1669:G1760) -> 15480.621 | N17: =SUM('Объединенные данные'!G526:G561) -> 14288.244 | O17: =SUM('Объединенные данные'!G1165:G1197) -> 6131.2492 | P17: =SUM('Объединенные данные'!G1805:G1831) -> 4388.816 | Q17: =SUM('Объединенные данные'!G591:G617) -> 5797.283 | R17: =SUM('Объединенные данные'!G1254:G1281) -> 14061.568 | S17: =SUM('Объединенные данные'!G1902:G1937) -> 15712.972 | T17: =SUM('Объединенные данные'!G618:G653) -> 37160.19 | U17: =SUM('Объединенные данные'!G1282:G1328) -> 31878.143 | V17: =SUM('Объединенные данные'!G1938:G2009) -> 31060.392
A18: abs | C18: =C17-B17 -> 26003.442 | D18: =D17-C17 -> 57934.55 | F18: =F17-E17 -> -428.77468 | G18: =G17-F17 -> 640.51549 | I18: =I17-H17 -> 26290.664 | J18: =J17-I17 -> -21955.647 | L18: =L17-K17 -> 722.1773 | M18: =M17-L17 -> 12879.486 | O18: =O17-N17 -> -8156.9948 | P18: =P17-O17 -> -1742.4332 | R18: =R17-Q17 -> 8264.2847 | S18: =S17-R17 -> 1651.4038 | U18: =U17-T17 -> -5282.0473 | V18: =V17-U17 -> -817.75047
A19: % | C19: =C18/B17 -> 0.18921432 | D19: =D18/C17 -> 0.35448729 | F19: =F18/E17 -> -0.075372969 | G19: =G18/F17 -> 0.12177259 | I19: =I18/H17 -> 0.052963363 | J19: =J18/I17 -> -0.04200558 | L19: =L18/K17 -> 0.38434982 | M19: =M18/L17 -> 4.9514856 | O19: =O18/N17 -> -0.57088854 | P19: =P18/O17 -> -0.28418894 | R19: =R18/Q17 -> 1.4255445 | S19: =S18/R17 -> 0.11744094 | U19: =U18/T17 -> -0.14214263 | V19: =V18/U17 -> -0.025652387
A20: L3M | B20: =SUM('Объединенные данные'!G111:G126) -> 39806.473 | C20: =SUM('Объединенные данные'!G768:G785) -> 52855.927 | D20: =SUM('Объединенные данные'!G1393:G1410) -> 62339.539 | E20: =SUM('Объединенные данные'!G162:G170) -> 1434.2134 | F20: =SUM('Объединенные данные'!G832:G840) -> 1186.4337 | G20: =SUM('Объединенные данные'!G1448:G1456) -> 1330.3696 | H20: =SUM('Объединенные данные'!G334:G378) -> 132694.48 | I20: =SUM('Объединенные данные'!G1050:G1058,'Объединенные данные'!G990:G1022) -> 135235.6 | J20: =SUM('Объединенные данные'!G1565:G1595,'Объединенные данные'!G1622:G1631) -> 114901.25 | K20: =SUM('Объединенные данные'!G434:G445) -> 514.57341 | L20: =SUM('Объединенные данные'!G1130:G1143) -> 1101.9023 | M20: =SUM('Объединенные данные'!G1741:G1760) -> 3596.8505 | N20: =SUM('Объединенные данные'!G553:G561) -> 2287.2661 | O20: =SUM('Объединенные данные'!G1190:G1197) -> 1575.3566 | P20: =SUM('Объединенные данные'!G1823:G1831) -> 1319.3385 | Q20: =SUM('Объединенные данные'!G612:G617) -> 1414.9637 | R20: =SUM('Объединенные данные'!G1273:G1281) -> 9069.3264 | S20: =SUM('Объединенные данные'!G1929:G1937) -> 2766.8657 | T20: =SUM('Объединенные данные'!G645:G653) -> 7758.9174 | U20: =SUM('Объединенные данные'!G1312:G1328) -> 7058.7773 | V20: =SUM('Объединенные данные'!G1992:G2009) -> 7944.9861
A21: abs | C21: =C20-B20 -> 13049.453 | D21: =D20-C20 -> 9483.6128 | F21: =F20-E20 -> -247.77967 | G21: =G20-F20 -> 143.93595 | I21: =I20-H20 -> 2541.1255 | J21: =J20-I20 -> -20334.352 | L21: =L20-K20 -> 587.32893 | M21: =M20-L20 -> 2494.9482 | O21: =O20-N20 -> -711.90948 | P21: =P20-O20 -> -256.01814 | R21: =R20-Q20 -> 7654.3626 | S21: =S20-R20 -> -6302.4607 | U21: =U20-T20 -> -700.14002 | V21: =V20-U20 -> 886.20877
A22: % | C22: =C21/B20 -> 0.32782239 | D22: =D21/C20 -> 0.17942383 | F22: =F21/E20 -> -0.17276347 | G22: =G21/F20 -> 0.12131816 | I22: =I21/H20 -> 0.019150198 | J22: =J21/I20 -> -0.15036242 | L22: =L21/K20 -> 1.14139 | M22: =M21/L20 -> 2.264219 | O22: =O21/N20 -> -0.31124908 | P22: =P21/O20 -> -0.1625144 | R22: =R21/Q20 -> 5.4095823 | S22: =S21/R20 -> -0.69492049 | U22: =U21/T20 -> -0.090236819 | V22: =V21/U20 -> 0.12554706
A23: M2M | B23: =SUM('Объединенные данные'!G121:G126) -> 12366.352 | C23: =SUM('Объединенные данные'!G780:G785) -> 16691.093 | D23: =SUM('Объединенные данные'!G1405:G1410) -> 19659.808 | E23: =SUM('Объединенные данные'!G168:G170) -> 413.24156 | F23: =SUM('Объединенные данные'!G838:G840) -> 423.04557 | G23: =SUM('Объединенные данные'!G1454:G1456) -> 471.34537 | H23: =SUM('Объединенные данные'!G376:G378,'Объединенные данные'!G358:G369) -> 45310.787 | I23: =SUM('Объединенные данные'!G1012:G1022,'Объединенные данные'!G1056:G1058) -> 43809.542 | J23: =SUM('Объединенные данные'!G1586:G1595,'Объединенные данные'!G1629:G1631) -> 35212.074 | K23: =SUM('Объединенные данные'!G442:G445) -> 155.77583 | L23: =SUM('Объединенные данные'!G1139:G1143) -> 391.54515 | M23: =SUM('Объединенные данные'!G1757:G1760) -> 1163.942 | N23: =SUM('Объединенные данные'!G559:G561) -> 631.44435 | O23: =SUM('Объединенные данные'!G1195:G1197) -> 527.7089 | P23: =SUM('Объединенные данные'!G1829:G1831) -> 451.35932 | Q23: =SUM('Объединенные данные'!G616:G617) -> 440.93899 | R23: =SUM('Объединенные данные'!G1279:G1281) -> 2581.2038 | S23: =SUM('Объединенные данные'!G1935:G1937) -> 824.36231 | T23: =SUM('Объединенные данные'!G651:G653) -> 2219.7372 | U23: =SUM('Объединенные данные'!G1323:G1328) -> 2267.3319 | V23: =SUM('Объединенные данные'!G2004:G2009) -> 2966.3081
A24: abs | C24: =C23-B23 -> 4324.7406 | D24: =D23-C23 -> 2968.7153 | F24: =F23-E23 -> 9.804014 | G24: =G23-F23 -> 48.299794 | I24: =I23-H23 -> -1501.2449 | J24: =J23-I23 -> -8597.4689 | L24: =L23-K23 -> 235.76932 | M24: =M23-L23 -> 772.39686 | O24: =O23-N23 -> -103.73544 | P24: =P23-O23 -> -76.34958 | R24: =R23-Q23 -> 2140.2648 | S24: =S23-R23 -> -1756.8414 | U24: =U23-T23 -> 47.594693 | V24: =V23-U23 -> 698.97622
A25: % | C25: =C24/B23 -> 0.34971837 | D25: =D24/C23 -> 0.17786225 | F25: =F24/E23 -> 0.023724657 | G25: =G24/F23 -> 0.11417161 | I25: =I24/H23 -> -0.033132174 | J25: =J24/I23 -> -0.19624649 | L25: =L24/K23 -> 1.5135168 | M25: =M24/L23 -> 1.9726891 | O25: =O24/N23 -> -0.1642828 | P25: =P24/O23 -> -0.14468124 | R25: =R24/Q23 -> 4.8538796 | S25: =S24/R23 -> -0.68062873 | U25: =U24/T23 -> 0.021441589 | V25: =V24/U23 -> 0.30828139
B29: 2020 | C29: 2021 | D29: 2022
A30: Green | B30: 496393.4 | C30: 471523.69 | D30: 500728.41
A31: Blue | B31: 137428.51 | C31: 163431.95 | D31: 221366.5
A32: Yellow | B32: 37160.19 | C32: 31878.143 | D32: 31060.392
A33: Red | B33: 14288.244 | C33: 6131.2492 | D33: 4388.816
A34: White | B34: 5797.283 | C34: 14061.568 | D34: 15712.972
A35: Deep | B35: 5688.7063 | C35: 5259.9316 | D35: 5900.4471
A36: Orange | B36: 1878.9583 | C36: 2601.1356 | D36: 15480.621
A62: Вывод: бренд Green занимает лидирующую позицию по объему продаж в деньгах. Но по относительным показателям рост продаж замедляется (FY > L3M > M2M)

Sheet Проверка качества данных
A1: проверка пустот в данных
A2: Year | B2: Month | C2: Channel | D2: Brand | E2: Weight range | F2: Units (in 1000) | G2: Value (in 1000 rub) | H2: Volume (in 1000 kg) | I2: Number of stores
A3: =COUNTBLANK(Копия_20206[Year]) -> 0 | B3: =COUNTBLANK(Копия_20206[Month]) -> 0 | C3: =COUNTBLANK(Копия_20206[Channel]) -> 0 | D3: =COUNTBLANK(Копия_20206[Brand]) -> 0 | E3: =COUNTBLANK(Копия_20206[Weight range]) -> 0 | F3: =COUNTBLANK(Копия_20206[Units (in 1000)]) -> 0 | G3: =COUNTBLANK(Копия_20206[Value (in 1000 rub)]) -> 0 | H3: =COUNTBLANK(Копия_20206[Volume (in 1000 kg)]) -> 0 | I3: =COUNTBLANK(Копия_20206[Number of stores]) -> 0
A5: market: | C5: brand: | E5: Weight range:
A6: Supermarkets | C6: Beige | E6: <200G
A7: Hypermarkets | C7: Black | E7: 100-199G
A8: Minimarkets | C8: Blue | E8: 200-249G
C9: Bone | E9: 250-299G
C10: Brown | E10: 300-349G
C11: Cotton | E11: 350-399G
C12: Cream | E12: 400-599G
C13: Daisy | E13: 600-899G
C14: Deep
C15: Delicate
C16: Dim
C17: Glossy
C18: Golden
C19: Green
C20: Grey
C21: Khaki
C22: Lilac
C23: Lime
C24: Linen
C25: Macaroon
... C46: Yellow
A48: Проверка качества данных показала отсутствие дубликатов, некорректно введенных данных, пропущенных значений. Размерности соответствуют содержимому.
A49: Очистка данных мною была проведена ранее. Был убран знак # у бренда Green, что могло существенно изменить результаты общих продаж в денежном выражении. В частности были бы искажены результаты за 2021 год
A50: В столбце Value (in 1000 rub) в некоторых ячейках присутствовал знак "+", что мешало дальнейшим вычислениям метрик и могло привести к неверным данным по продажам
A52: Динамика роста продаж в деньгах для всего рынка за 2021 и 2022 года
B53: бренд Blue | E53: бренд Deep | H53: бренд Green | K53: бренд Orange | N53: бренд Red | Q53: бренд White | T53: бренд Yellow
A54: год | B54: 2020 | C54: 2021 | D54: 2022 | E54: 2020 | F54: 2021 | G54: 2022 | H54: 2020 | I54: 2021 | J54: 2022 | K54: 2020 | L54: 2021 | M54: 2022 | N54: 2020 | O54: 2021 | P54: 2022 | Q54: 2020 | R54: 2021 | S54: 2022 | T54: 2020 | U54: 2021 | V54: 2022
A55: FY | B55: =SUM('Объединенные данные'!G84:G126) -> 137428.51 | C55: =SUM('Объединенные данные'!G714:G785) -> 163431.95 | D55: =SUM('Объединенные данные'!G1339:G1410) -> 221366.5 | E55: =SUM('Объединенные данные'!G133:G170) -> 5688.7063 | F55: =SUM('Объединенные данные'!G805:G840) -> 5259.9316 | G55: =SUM('Объединенные данные'!G1421:G1456) -> 5900.4471 | H55: =SUM('Объединенные данные'!G217:G378) -> 496393.4 | I55: =SUM('Объединенные данные'!G890:G1058) -> 522684.06 | J55: =SUM('Объединенные данные'!G1465:G1631) -> 500728.41 | K55: =SUM('Объединенные данные'!G402:G445) -> 1878.9583 | L55: =SUM('Объединенные данные'!G1102:G1143) -> 2601.1356 | M55: =SUM('Объединенные данные'!G1669:G1760) -> 15480.621 | N55: =SUM('Объединенные данные'!G526:G561) -> 14288.244 | O55: =SUM('Объединенные данные'!G1165:G1197) -> 6131.2492 | P55: =SUM('Объединенные данные'!G1805:G1831) -> 4388.816 | Q55: =SUM('Объединенные данные'!G591:G617) -> 5797.283 | R55: =SUM('Объединенные данные'!G1254:G1281) -> 14061.568 | S55: =SUM('Объединенные данные'!G1902:G1937) -> 15712.972 | T55: =SUM('Объединенные данные'!G618:G653) -> 37160.19 | U55: =SUM('Объединенные данные'!G1282:G1328) -> 31878.143 | V55: =SUM('Объединенные данные'!G1938:G2009) -> 31060.392
A56: abs | C56: =C55-B55 -> 26003.442 | D56: =D55-C55 -> 57934.55 | F56: =F55-E55 -> -428.77468 | G56: =G55-F55 -> 640.51549 | I56: =I55-H55 -> 26290.664 | J56: =J55-I55 -> -21955.647 | L56: =L55-K55 -> 722.1773 | M56: =M55-L55 -> 12879.486 | O56: =O55-N55 -> -8156.9948 | P56: =P55-O55 -> -1742.4332 | R56: =R55-Q55 -> 8264.2847 | S56: =S55-R55 -> 1651.4038 | U56: =U55-T55 -> -5282.0473 | V56: =V55-U55 -> -817.75047
A57: % | C57: =C56/B55 -> 0.18921432 | D57: =D56/C55 -> 0.35448729 | F57: =F56/E55 -> -0.075372969 | G57: =G56/F55 -> 0.12177259 | I57: =I56/H55 -> 0.052963363 | J57: =J56/I55 -> -0.04200558 | L57: =L56/K55 -> 0.38434982 | M57: =M56/L55 -> 4.9514856 | O57: =O56/N55 -> -0.57088854 | P57: =P56/O55 -> -0.28418894 | R57: =R56/Q55 -> 1.4255445 | S57: =S56/R55 -> 0.11744094 | U57: =U56/T55 -> -0.14214263 | V57: =V56/U55 -> -0.025652387
A59: Метрики получились такими же, но это при наличии выбросов.

Sheet Показатели
A1: 1. Отобразить топ-5 брендов в каждом канале продаж (ГМ, СМ, ММ) в денежном выражении в 2022 году.
A3: Year | B3: 2022
A5: Сумма по полю Value (in 1000 rub) | B5: Названия столбцов
A6: Названия строк | B6: Hypermarkets | C6: Minimarkets | D6: Supermarkets | E6: Общий итог
A7: Green | B7: 118318.65 | C7: 110107.78 | D7: 272301.98 | E7: 500728.41
A8: Blue | B8: 87186.432 | C8: 28378.209 | D8: 105801.86 | E8: 221366.5
A9: Orange | B9: 4990.2211 | C9: 1750.1118 | D9: 8740.2883 | E9: 15480.621
A10: White | B10: 3412.6708 | C10: 4424.6321 | D10: 7875.6686 | E10: 15712.972
A11: Yellow | B11: 2041.4898 | C11: 7788.6439 | D11: 21230.259 | E11: 31060.392
A12: Red | B12: 1050.0328 | C12: 1093.6669 | D12: 2245.1163 | E12: 4388.816
A13: Macaroon | B13: 918.25091 | C13: 744.7961 | D13: 344.14095 | E13: 2007.188
A14: Pearl | B14: 822.02257 | C14: 1633.2928 | D14: 10974.993 | E14: 13430.308
A15: Purple | B15: 426.93184 | E15: 426.93184
A16: Magenta | B16: 395.23323 | C16: 778.48601 | D16: 1100.0053 | E16: 2273.7246
A17: Bone | B17: 330.19772 | C17: 315.2459 | E17: 645.44361
A18: Rice | B18: 202.86361 | D18: 538.26801 | E18: 741.13162
A19: Lime | B19: 182.54365 | E19: 182.54365
A20: Rosy | B20: 140.7518 | C20: 1674.8391 | D20: 3822.237 | E20: 5637.8279
A21: Pink | B21: 67.815393 | E21: 67.815393
A22: Powder | B22: 34.264124 | E22: 34.264124
A23: Cotton | B23: 32.450189 | E23: 32.450189
A24: Snow | C24: 885.1923 | D24: 308.90372 | E24: 1194.096
A25: Lilac | C25: 191.71571 | E25: 191.71571
A26: Linen | C26: 41.641205 | D26: 198.9849 | E26: 240.62611
A27: Vivid | D27: 1197.3276 | E27: 1197.3276
A28: Daisy | C28: 163.77075 | E28: 163.77075
A29: Black | C29: 428.72449 | E29: 428.72449
A30: Deep | D30: 5900.4471 | E30: 5900.4471
A31: Dim | D31: 1456.9284 | E31: 1456.9284
A32: Общий итог | B32: 220552.82 | C32: 160400.75 | D32: 444037.41 | E32: 824990.98
A35: Hypermarkets | D35: Supermarket | G35: Minimarkets
A36: Green | B36: 118318.65 | D36: Green | E36: 272301.98 | G36: Green | H36: 110107.78
A37: Blue | B37: 87186.432 | D37: Blue | E37: 105801.86 | G37: Blue | H37: 28378.209
A38: Orange | B38: 4990.2211 | D38: Yellow | E38: 21230.259 | G38: Yellow | H38: 7788.6439
A39: White | B39: 3412.6708 | D39: Pearl | E39: 10974.993 | G39: White | H39: 4424.6321
A40: Yellow | B40: 2041.4898 | D40: Orange | E40: 8740.2883 | G40: Orange | H40: 1750.1118
A43: Вывод: В каждом из каналов первые 2 лидирующих места занимают бренды Green и Blue. При этом в канале Hypermarket цифры продаж довольно близки по значению
A47: 2. Годовая доля рынка в денежном выражении в 2022 году среди брендов объединённых групп weight ranges 350-599G в канале СМ
A49: Year | B49: 2022
A50: Channel | B50: Supermarkets
...

Sheet Гипотезы
A1: Различается ли распределение продаж по брендам в разрезе каналов?
A2: Гипотеза: Распределение продаж по брендам в разрезе каналов различается
A3: Н0: Распределение продаж по брендам в разрезе каналов не отличается
A4: Сумма по полю Value (in 1000 rub) | B4: Названия столбцов
A5: Названия строк | B5: Hypermarkets | C5: Minimarkets | D5: Supermarkets | E5: Общий итог
A6: Beige | B6: 0 | C6: 0 | D6: 1 | E6: 1
A7: Black | B7: 0.29762934 | C7: 0.23912804 | D7: 0.46324263 | E7: 1
A8: Blue | B8: 0.37816631 | C8: 0.12336974 | D8: 0.49846395 | E8: 1
A9: Bone | B9: 0.51158259 | C9: 0.48841741 | D9: 0 | E9: 1
A10: Brown | B10: 1 | C10: 0 | D10: 0 | E10: 1
A11: Cotton | B11: 1 | C11: 0 | D11: 0 | E11: 1
A12: Cream | B12: 0 | C12: 0 | D12: 1 | E12: 1
A13: Daisy | B13: 0 | C13: 1 | D13: 0 | E13: 1
A14: Deep | B14: 0.0033176754 | C14: 0 | D14: 0.99668232 | E14: 1
A15: Delicate | B15: 0 | C15: 0.29676963 | D15: 0.70323037 | E15: 1
A16: Dim | B16: 0 | C16: 0 | D16: 1 | E16: 1
A17: Glossy | B17: 0 | C17: 0 | D17: 1 | E17: 1
... A47: Общий итог | B47: 0.27102401 | C47: 0.21443755 | D47: 0.51453844 | E47: 1
A79: Наглядно видно, что у всех брендов продажи распределены неравномерно. Т.е. гипотеза о различии распределения продаж по брендам в разрезе каналов подтвердилась.
A83: Почему офтейк на точку в штуках различается по каналам?
A84: Гипотеза: офтейк в штуках различается по каналам
A85: Н0: офтейк не различается по каналам
A86: Year | B86: 2022
A88: Названия строк | B88: Сумма по полю Units (in 1000) | C88: Сумма по полю Number of stores
A89: Hypermarkets | B89: 1734.7102 | C89: 41990
A90: Minimarkets | B90: 1607.3944 | C90: 298436
A91: Supermarkets | B91: 4249.5564 | C91: 568684
A92: Общий итог | B92: 7591.661 | C92: 909110
A95: Названия строк | B95: Сумма по полю Units | C95: Сумма по полю Number of stores
A96: Hypermarkets | B96: =1734.7102*(1000) -> 1734710.2 | C96: 41990
A97: Minimarkets | B97: =1607.3944*(1000) -> 1607394.4 | C97: 298436
A98: Supermarkets | B98: =4249.5564*(1000) -> 4249556.4 | C98: 568684
A121: Поскольку распределение и по количеству проданных единиц товара, и по количеству магазинов в разрезе каналов не одинаковое, то и оффтейк на точку получается разным для разных каналов продаж
A125: Как различаются цены по каналам?
A126: Гипотеза: цены по каналам различаются.
A127: Н0: цены по каналам не различаются
A128: Year | B128: 2022
B130: Названия столбцов
B131: Hypermarkets | C131: Minimarkets | D131: Supermarkets | E131: Общий итог
A132: Сумма по полю Avg month | B132: 127.14102 | C132: 99.789292 | D132: 104.4903 | E132: 108.67068
...

Sheet Визуализация
A1: Покажите динамику объёма продаж в деньгах во всей категории по месяцам за три года.
B2: 2020 | N2: 2021 | Z2: 2022
A3: месяц | B3: 1 | C3: 2 | D3: 3 | E3: 4 | F3: 5 | G3: 6 | H3: 7 | I3: 8 | J3: 9 | K3: 10 | L3: 11 | M3: 12 | N3: 1 | O3: 2 | P3: 3 | Q3: 4 | R3: 5 | S3: 6 | T3: 7 | U3: 8 | V3: 9 | W3: 10 | X3: 11 | Y3: 12 | Z3: 1 | AA3: 2 | AB3: 3 | AC3: 4 | AD3: 5 | AE3: 6 | AF3: 7 | AG3: 8 | AH3: 9 | AI3: 10 | AJ3: 11 | AK3: 12
A4: Объем продаж | B4: 76736.703 | C4: 66754.411 | D4: 68140.292 | E4: 62152.611 | F4: 56780.285 | G4: 53331.762 | H4: 52147.32 | I4: 53673.44 | J4: 59271.082 | K4: 64614.677 | L4: 66150.411 | M4: 65067.566 | N4: 69190.693 | O4: 59878.986 | P4: 68476.052 | Q4: 61190.15 | R4: 65412.256 | S4: 59387.81 | T4: 67089.521 | U4: 62303.908 | V4: 65116.916 | W4: 75724.564 | X4: 70662.723 | Y4: 68524.721 | Z4: 77745.387 | AA4: 69359.302 | AB4: 97898.93 | AC4: 76312.47 | AD4: 68963.913 | AE4: 56583.198 | AF4: 62134.868 | AG4: 57345.907 | AH4: 57412.959 | AI4: 71325.113 | AJ4: 66521.687 | AK4: 63387.249
A36: Визуализируйте годовую долю рынка в денежном выражении за 2022 год среди брендов объединённых весовых групп 350-599G в канале СМ.
B38: Доля продаж
A39: Green | B39: 0.81689902
A40: Yellow | B40: 0.091118918
A41: Pearl | B41: 0.051699754
A42: Rosy | B42: 0.016505776
A43: Red | B43: 0.01057604
A44: Vivid | B44: 0.0037913505
A45: Dim | B45: 0.0033064294
A46: Rice | B46: 0.002535612
A47: Macaroon | B47: 0.0016211402
A48: Snow | B48: 0.0014551487
A49: Deep | B49: 0.00049081226
A80: Отобразите на одном графике динамику доли рынка в денежном выражении на каждый месяц за последние два года каждого топ-5 брендов объединённых групп weight ranges 350-599G в канале СМ.
A81: Долю остальных брендов сгруппируйте, назовите Others и также разместите на графике. Топ-5 брендов определите по совокупной доле за 2021 и 2022 годы.
B83: 1 | C83: 2 | D83: 3 | E83: 4 | F83: 5 | G83: 6 | H83: 7 | I83: 8 | J83: 9 | K83: 10 | L83: 11 | M83: 12
A84: Green | B84: 0.54932163 | C84: 0.59246929 | D84: 0.52687778 | E84: 0.58638202 | F84: 0.51898622 | G84: 0.55378388 | H84: 0.5367592 | I84: 0.58775512 | J84: 0.58405523 | K84: 0.5977989 | L84: 0.53315578 | M84: 0.58599131
A85: Blue | B85: 0.32909079 | C85: 0.25133373 | D85: 0.33270344 | E85: 0.247911 | F85: 0.27765036 | G85: 0.25126398 | H85: 0.28070584 | I85: 0.26175199 | J85: 0.25620819 | K85: 0.29411428 | L85: 0.34056286 | M85: 0.29127501
A86: Yellow | B86: 0.062188845 | C86: 0.075293034 | D86: 0.063605604 | E86: 0.077644649 | F86: 0.062093308 | G86: 0.05129102 | H86: 0.065230714 | I86: 0.046258877 | J86: 0.07964939 | K86: 0.036880667 | L86: 0.06017043 | M86: 0.055592149
A87: Rosy | B87: 0.0079968652 | C87: 0.0087120996 | D87: 0.0065959601 | E87: 0.007406617 | F87: 0.052117956 | G87: 0.061394331 | H87: 0.047377896 | I87: 0.03958188 | J87: 0.024873132 | K87: 0.017829467 | L87: 0.013352105 | M87: 0.0061231513
A88: Pearl | B88: 0 | C88: 0.0096498082 | D88: 0.015388957 | E88: 0.017468374 | F88: 0.018211219 | G88: 0.017865345 | H88: 0.01623175 | I88: 0.021276893 | J88: 0.02039222 | K88: 0.020044379 | L88: 0.023187687 | M88: 0.022132811
A89: Other | B89: =SUM(B92:B106) -> 0.051401869 | C89: =SUM(C92:C106) -> 0.062542038 | D89: =SUM(D92:D106) -> 0.054828259 | E89: =SUM(E92:E106) -> 0.063187339 | F89: =SUM(F92:F106) -> 0.070940936 | G89: =SUM(G92:G106) -> 0.06440144 | H89: =SUM(H92:H106) -> 0.053694594 | I89: =SUM(I92:I106) -> 0.043375242 | ... M89: =SUM(M92:M106) -> 0.038885573
B91: Other
A92: Orange | B92: 0.0047665591 | C92: 0.017763817 | D92: 0.016809057 | E92: 0.02008984 | F92: 0.020858615 | G92: 0.013339908 | H92: 0.011430989 | I92: 0.010201156 | J92: 0.0090884103 | K92: 0.011184839 | L92: 0.013849583 | M92: 0.016931888
A93: Red | B93: 0.011381124 | C93: 0.011413669 | D93: 0.0075483521 | E93: 0.014839696 | F93: 0.0061674097 | G93: 0.013248975 | H93: 0.0043066341 | I93: 0.005253858 | J93: 0.01144465 | K93: 0.010686928 | L93: 0.0098971405 | M93: 0.0091987473
A94: Dim | B94: 0.0035476151 | C94: 0.005813732 | D94: 0.012153602 | E94: 0.012841832 | F94: 0.010851545 | G94: 0.0046211213 | H94: 0.0037554516 | I94: 0.0040856772 | J94: 0.0053801718 | K94: 0.0052787113 | L94: 0 | M94: 0.0035818129
A95: Golden | B95: 0 | C95: 0 | D95: 0 | E95: 0 | F95: 0.016177536 | G95: 0.022487325 | H95: 0.018352814 | I95: 0.010902457 | J95: 0.0052817813 | K95: 0.0029519831 | L95: 0 | M95: 0
A96: Black | B96: 0.01472048 | C96: 0.011828949 | D96: 0.0062041396 | E96: 0.0068553992 | F96: 0.0084396271 | G96: 0.00713133 | H96: 0.0066223536 | I96: 0.003387809 | J96: 0 | K96: 0 | L96: 0 | M96: 0
A97: Vivid | B97: 0.0071658369 | C97: 0.0044104348 | D97: 0.003310547 | E97: 0 | F97: 0 | G97: 0 | H97: 0 | I97: 0.0019632148 | J97: 0.0024524608 | K97: 0.0022208975 | L97: 0.002496458 | M97: 0.0024400896
A98: Deep | B98: 0.001512574 | C98: 0.0022523183 | D98: 0.0025843545 | E98: 0.0023813598 | F98: 0.0017379509 | G98: 0.0015137881 | H98: 0.0011206428 | I98: 0.0013572088 | J98: 0.0011743595 | K98: 0.0010089435 | L98: 0.0011500449 | M98: 0.0013070967
A99: Moderate | B99: 0.0042666279 | C99: 0.004719645 | D99: 0.0031021773 | E99: 0.0038998309 | F99: 0 | G99: 0 | H99: 0 | I99: 0 | J99: 0 | K99: 0 | L99: 0 | M99: 0
A100: Pale | B100: 0.0040410526 | C100: 0.0043394727 | D100: 0.0031160296 | E100: 0 | F100: 0 | G100: 0 | H100: 0 | I100: 0 | J100: 0 | K100: 0 | L100: 0 | M100: 0
A101: Rice | B101: 0 | C101: 0 | D101: 0 | E101: 0 | F101: 0 | G101: 0 | H101: 0.0042981092 | I101: 0.0062238612 | J101: 0 | K101: 0 | L101: 0 | M101: 0
A102: Macaroon | B102: 0 | C102: 0 | D102: 0 | E102: 0 | F102: 0.0067082523 | G102: 0 | H102: 0 | I102: 0 | J102: 0 | K102: 0 | L102: 0 | M102: 0
A103: Snow | B103: 0 | C103: 0 | D103: 0 | E103: 0 | F103: 0 | G103: 0 | H103: 0 | I103: 0 | J103: 0 | K103: 0 | L103: 0 | M103: 0.0054259381
... A106: Cream | B106: 0 | C106: 0 | D106: 0 | E106: 0 | F106: 0 | G106: 0.002058993 | H106: 0 | I106: 0 | J106: 0 | K106: 0 | L106: 0 | M106: 0
...
